Workbook
Name _GoBack: '4.1 Design & Construction'!$A$10

Sheet 2030
C2: Global | D2: LAyC | E2: Argentina
B4: 1990 | C4: 756 | D4: 709 | E4: 612
B6: 2000 | C6: 711 | D6: 652 | E6: 601
B8: 2010 | C8: 634 | D8: 603 | E8: 570
B10: 2020 | C10: 624 | D10: 589 | E10: 507
C11: Meta No Condicionada | D11: Meta Condicionada
B12: 2030 | D12: 500

Sheet LB
B2: ESCENARIO EMISIONES 2020 - 2050
B4: Las emisiones proyectadas al año 2050 se calculan a partir de la línea base de emisiones al año 2020(*), y el incremento de producción de cemento al 2050 sin eficiencias (58%), según escenario BAU (Business as Usual), que significa producir y utilizar el cemento bajo las mismas condiciones actuales en el 2050.
B8: Las emisiones LB2020 fueron 6,9 MtCO2e, considerando emisiones directas (6,5 MtCO2e) e indirectas del uso de energía eléctrica (0,4 MtCO2e). Al año 2050, se consideró un aumento del 58% del consumo de cemento, que implica llegar a 19,5 Mt, lo que significaría 10,7 MtCO2e de emisiones totales BAU.
B12: AUMENTO DEMANDA | L12: PROYECCION EMISIONES TOTALES BAU
B48: Aumento Demanda | C48: 2020 | D48: 2030 | E48: 2040 | F48: 2050 | L48: Emisiones Totales | M48: 2020 | N48: 2030 | O48: 2040 | P48: 2050
B49: FICEM | C49: 0 | D49: 20 | E49: =AVERAGE(D49,F49) -> 45 | F49: 70 | L49: FICEM | M49: 126 | N49: 151 | O49: =AVERAGE(N49,P49) -> 182.5 | P49: 214
B50: Perú | C50: 0 | D50: 20 | E50: =AVERAGE(D50,F50) -> 50 | F50: 80 | L50: Perú | M50: 6.7 | N50: 8.1 | O50: =AVERAGE(N50,P50) -> 10.15 | P50: 12.2
B51: Colombia | C51: 0 | D51: 20 | E51: =AVERAGE(D51,F51) -> 35 | F51: 50 | L51: Colombia | M51: 8.4 | N51: 9.5 | O51: =AVERAGE(N51,P51) -> 11.1 | P51: 12.7 | S51: SE DEJA COMPARACION CON PAISES
B52: Chile | C52: 0 | D52: 10 | E52: =AVERAGE(D52,F52) -> 25 | F52: 40 | L52: Chile | M52: 3.8 | N52: 4 | O52: =AVERAGE(N52,P52) -> 4.35 | P52: 4.7 | S52: FICEM SE CAMBIA POR COMPAÑÍA
B53: ARGENTINA | C53: =+M60 -> 0 | D53: =+N60 -> 18 | E53: =+AVERAGE(D53,F53) -> 36.5 | F53: =+P60 -> 55 | L53: Argentina | M53: =+M63 -> 6.8665 | N53: =+N63 -> 8.10247 | O53: =+O63 -> 9.3130537 | P53: =+P63 -> 10.643075 | S53: ARGENTINA SE SUMA INDEPENDIENTE
B54: GCCA Roadmap | C54: 0 | D54: 14.545455 | E54: =AVERAGE(D54,F54) -> 33.272727 | F54: 52
L56: EMISIONES ESCENARIO BAU | M56: 2020 | N56: 2030 | O56: 2040 | P56: 2050
L57: Clínker BAU [Mt] | M57: 8.5 | N57: =+M57*(1+N60/100) -> 10.03 | O57: =+AVERAGE(N57,P57) -> 11.6025 | P57: =+M57*(1+P60/100) -> 13.175
L58: Cemento BAU [Mt] | M58: 12.5 | N58: =+M58*(1+N60/100) -> 14.75 | O58: =+AVERAGE(N58,P58) -> 17.0625 | P58: =+M58*(1+P60/100) -> 19.375
L59: FE Clinker BAU [kgCO2/tck] | M59: 749 | N59: 749 | O59: =+AVERAGE(N59,P59) -> 749 | P59: 749
L60: Aumento Demanda Escenario BAU [%] | M60: 0 | N60: 18 | O60: =+AVERAGE(N60,P60) -> 36.5 | P60: 55
L61: Emisiones Directas Clinker BAU [MtCO2] | M61: =+M59*M57/1000 -> 6.3665 | N61: =+N59*N57/1000 -> 7.51247 | O61: =+O59*O57/1000 -> 8.6902725 | P61: =+P59*P57/1000 -> 9.868075
L62: Emisiones Alcance 2 BAU [MTCO2] | M62: 0.5 | N62: 0.3 | O62: =+O60*O58/1000 -> 0.62278125 | P62: 0.6
L63: Emisiones Totales BAU [MTCO2] | M63: =+M62+M61 -> 6.8665 | N63: =+M63*(1+N60/100) -> 8.10247 | O63: =+O62+O61 -> 9.3130537 | P63: =+M63*(1+P60/100) -> 10.643075

Sheet Eje 1-1
C2: DISEÑO Y CONSTRUCCION
C4: Aumentar la eficiencia en el uso de concreto en la construcción, a través de la inclusión de etapas y actividades aguas arriba y aguas abajo de la industria del cemento y concreto – como diseño, planificación, especificación y construcción – significa, entre otros, no sobre utilizar concreto, si no el volumen más bajo posible que cumpla con los requisitos de aplicación sin comprometer durabilidad y seguridad.
C9: Algunas aplicaciones son: elementos de fachada tipo sándwich; diseño con AI y optimización elementos estructurales; cálculos de diseño lineal/elásticos hasta cálculos basados en plasticidad, reutilización residuos de concreto, entre otros. Proyectistas, diseñadores, especificadores, inspectores y directores de obra, contratistas y el Poder Público tienen un rol central para su despliegue.

Sheet Eje 1-2
B2: EFICIENCIA PRODUCCION CONCRETO
B4: La optimización en la producción de concreto, implica hacer más eficiente el uso del cemento en el concreto, para una prestación de referencia, reduciendo, además, la huella de carbono del concreto. Esta mejora se debe lograr sin comprometer la calidad del producto.
B7: Actualmente, la composición de la fabricación del concreto en LAC, se distribuye de la siguiente manera: 28% de premezclado, 64% de cemento en sacos; 5% de mezcla en silos de obra; 3% de prefabricados. Se proyecta, que para el año 2050, la distribución sea de la siguiente forma: 45% de premezclado, 40% de cemento en sacos; 5% de mezcla en silos de obra; 10% de prefabricados; aumentando así la industrialización en este proceso.
B11: % CEMENTO EN SACOS | K11: % READYMIX | U11: % CEMENTO EN SILOS OBRA | AF11: % PREFABRICADOS
B47: % Cemento Sacos | C47: 2020 | D47: 2030 | E47: 2040 | F47: 2050 | L47: % Readymix | M47: 2020 | N47: 2030 | O47: 2040 | P47: 2050 | U47: % Silos | V47: 2020 | W47: 2030 | X47: 2040 | Y47: 2050 | AF47: % Prefabricados | AG47: 2020 | AH47: 2030 | AI47: 2040 | AJ47: 2050
B48: FICEM | C48: 64 | D48: 59 | E48: =AVERAGE(D48,F48) -> 49.5 | F48: 40 | L48: FICEM | M48: 28 | N48: 33 | O48: =AVERAGE(N48,P48) -> 39 | P48: 45 | U48: FICEM | V48: 5 | W48: 5 | X48: =AVERAGE(W48,Y48) -> 5 | Y48: 5 | AF48: FICEM | AG48: 3 | AH48: 3 | AI48: =AVERAGE(AH48,AJ48) -> 6.5 | AJ48: 10
B49: Perú | C49: 78.1 | D49: 75 | E49: =+AVERAGE(D49,F49) -> 72.5 | F49: 70 | L49: Perú | M49: 17 | N49: 24 | O49: =+AVERAGE(N49,P49) -> 29 | P49: 34 | U49: Perú | V49: 3 | W49: 6 | X49: =+AVERAGE(W49,Y49) -> 6.5 | Y49: 7 | AF49: Perú | AG49: 1 | AH49: 2 | AI49: =+AVERAGE(AH49,AJ49) -> 3 | AJ49: 4
B50: Colombia | C50: 69 | D50: 64 | E50: =AVERAGE(D50,F50) -> 57 | F50: 50 | L50: Colombia | M50: 23 | N50: 26 | O50: =AVERAGE(N50,P50) -> 30.5 | P50: 35 | U50: Colombia | V50: 6 | W50: 5 | X50: =AVERAGE(W50,Y50) -> 7.5 | Y50: 10 | AF50: Colombia | AG50: 3 | AH50: 5 | AI50: =AVERAGE(AH50,AJ50) -> 5 | AJ50: 5
B51: Chile | C51: 30 | D51: 25 | E51: =AVERAGE(D51,F51) -> 17.5 | F51: 10 | L51: Chile | M51: 55 | N51: 60 | O51: =AVERAGE(N51,P51) -> 65 | P51: 70 | U51: Chile | V51: 10 | W51: 5 | X51: =AVERAGE(W51,Y51) -> 7.5 | Y51: 10 | AF51: Chile | AG51: 5 | AH51: 10 | AI51: =AVERAGE(AH51,AJ51) -> 12.5 | AJ51: 15
B52: ARGENTINA | C52: 53 | D52: 47 | E52: =AVERAGE(D52,F52) -> 45 | F52: 43 | L52: ARGENTINA | M52: 35 | N52: 39 | O52: =AVERAGE(N52,P52) -> 40.5 | P52: 42 | U52: ARGENTINA | V52: 7 | W52: 7 | X52: =AVERAGE(W52,Y52) -> 7 | Y52: 7 | AF52: ARGENTINA | AG52: 5 | AH52: 7 | AI52: =AVERAGE(AH52,AJ52) -> 7 | AJ52: 7
C54: 2020 | D54: 2030 | E54: 2040 | F54: 2050
B55: Sacos | C55: 53.3 | D55: 47 | E55: 45 | F55: 43
B56: Factor Clínker | C56: 58 | D56: 55 | E56: =+AVERAGE(D56,F56) -> 53.5 | F56: 52 | L56: COMPOSICION CONCRETO | M56: 2020 | N56: 2030 | O56: 2040 | P56: 2050 | U56: % y FCk por Canal | V56: 2020 | W56: 2030 | X56: 2040 | Y56: 2050
B57: Readymix | C57: 35 | D57: 39 | E57: 41 | F57: 42 | L57: Volumen Total Concreto [Mm3] | M57: 48.4 | N57: 57.1 | O57: =+AVERAGE(N57,P57) -> 66.05 | P57: 75 | U57: % Readymix | V57: 35 | W57: 39 | X57: 41 | Y57: 42
B58: Factor Clínker | C58: 78 | D58: 75 | E58: =+AVERAGE(D58,F58) -> 72 | F58: 69 | L58: Participacion Premezclado [%] | M58: 0.35 | N58: 0.39 | O58: =+AVERAGE(N58,P58) -> 0.445 | P58: 0.5 | U58: FCk
B59: Silos Obra | C59: 7 | D59: 7 | E59: 7 | F59: 7 | L59: Participacion Sacos [%] | M59: 0.48 | N59: 0.47 | O59: =AVERAGE(N59,P59) -> 0.385 | P59: 0.3 | U59: Sacos
B60: Factor Clínker | C60: 77 | D60: 72 | E60: =+AVERAGE(D60,F60) -> 69.5 | F60: 67 | L60: Participacion Silos [%] | M60: 0.06 | N60: 0.07 | O60: =+AVERAGE(N60,P60) -> 0.085 | P60: 0.1 | U60: FCk
B61: Precast | C61: 5 | D61: 7 | E61: 7 | F61: 7 | L61: Participacion Prefabricados [%] | M61: 0.08 | N61: 0.07 | O61: =+AVERAGE(N61,P61) -> 0.085 | P61: 0.1 | U61: Silos
B62: Factor Clínker | C62: 80 | D62: 75 | E62: =+AVERAGE(D62,F62) -> 71 | F62: 67 | L62: CEMENTO EN CONCRETO [kgCem/m3) | M62: 380 | N62: 375 | O62: =+AVERAGE(N62,P62) -> 360.5 | P62: 346 | U62: FCk
U63: Precast
C64: =+(C55*C56+C57*C58+C59*C60+C61*C62)/100 -> 67.604 | D64: =+(D55*D56+D57*D58+D59*D60+D61*D62)/100 -> 65.39 | E64: =+(E55*E56+E57*E58+E59*E60+E61*E62)/100 -> 63.43 | F64: =+(F55*F56+F57*F58+F59*F60+F61*F62)/100 -> 60.72 | U64: FCk

Sheet Eje 2
B5: CEMENTO EN CONCRETO
O38: CEMENTO [Mt] | P38: 2020 | Q38: 2030 | R38: 2040 | S38: 2050
C39: CEMENTO EN CONCRETO | D39: 2020 | E39: 2030 | F39: 2040 | G39: 2050 | O39: CEMENTO BAU | P39: 12.5 | Q39: 14.8 | R39: =+AVERAGE(Q39,S39) -> 17.1 | S39: 19.4
C40: FICEM | D40: 451 | E40: 447 | F40: =+AVERAGE(E40,G40) -> 401.5 | G40: 356 | O40: CEMENTO NZA | P40: 12.5 | Q40: 14.1 | R40: =+AVERAGE(Q40,S40) -> 15.7 | S40: 17.3
C41: Perú | D41: 366 | E41: 322 | F41: =+AVERAGE(E41,G41) -> 316 | G41: 310
C42: Colombia | D42: 366 | E42: 333 | F42: =+AVERAGE(E42,G42) -> 316.5 | G42: 300 | O42: CONCRETO
C43: Chile | D43: 354 | E43: 347 | F43: =+AVERAGE(E43,G43) -> 336.5 | G43: 326 | O43: Mm3 | P43: 34 | Q43: 46 | R43: =+AVERAGE(Q43,S43) -> 51.5 | S43: 57
C44: ARGENTINA | D44: 381.5 | E44: 377.1 | F44: =+AVERAGE(E44,G44) -> 356.05 | G44: 335
O45: CEMENTO/CONCRETO
O46: kgCem/m3 | P46: =+P40/P43*1000 -> 367.64706 | Q46: =+Q40/Q43*1000 -> 306.52174 | R46: =+R40/R43*1000 -> 304.85437 | S46: =+S40/S43*1000 -> 303.50877

Sheet Eje 3
C3: CEMENTO Y ADICIONES
B5: El parámetro más importante para determinar las emisiones de CO2e del cemento es su contenido o porcentaje de clínker, que se conoce como factor clínker. A nivel global, según datos reportados en GNR al año 2022, el factor clínker fue de 77%, el cual junto al yeso (5%), caliza (9%), puzolana (2%), escoria (3%); cenizas (3%) y otras adiciones (1%), forman el cemento.
B9: En LAC, el porcentaje de clínker es de 67%, 10 puntos porcentuales bajo el valor global, debido a la mayor disponibilidad de adiciones como las puzolanas, escoria y cenizas en nuestra región lo que resulta en un producto con menores emisiones de CO2e. Los porcentajes de composición del cemento en LAC son los siguientes: yeso (6%), caliza (11%), puzolana (11%), escoria (2%); cenizas (2%) y otras adiciones (1%) y clínker (67%).
B13: FACTOR CLINKER | M13: FACTOR CLINKER POR CANAL ARGENTINA | W13: PARTICIPACION POR CANAL
M46: FACTOR CLINKER CANAL | N46: 2020 | O46: 2030 | P46: 2040 | Q46: 2050 | X46: CANAL | Y46: 2020 | Z46: 2030 | AA46: 2040 | AB46: 2050
C47: Factor Clinker | D47: 2020 | E47: 2030 | F47: 2040 | G47: 2050 | M47: FCk Readymix | N47: 0.78 | O47: 0.75 | P47: =+AVERAGE(O47,Q47) -> 0.72 | Q47: 0.69 | X47: Concreto Mm3 | Y47: 33 | Z47: 38 | AA47: =+AVERAGE(Z47,AB47) -> 44 | AB47: 50
C48: FICEM | D48: 67 | E48: 66 | F48: =AVERAGE(E48,G48) -> 63 | G48: 60 | M48: FCk Sacos | N48: 0.58 | O48: 0.55 | P48: =+AVERAGE(O48,Q48) -> 0.535 | Q48: 0.52 | X48: Premezclado [%] | Y48: 0.35 | Z48: 0.39 | AA48: =+AVERAGE(Z48,AB48) -> 0.405 | AB48: 0.42
C49: Perú | D49: 75 | E49: 70 | F49: =AVERAGE(E49,G49) -> 68.5 | G49: 67 | M49: FCk Silos | N49: 0.77 | O49: 0.72 | P49: =AVERAGE(O49,Q49) -> 0.695 | Q49: 0.67 | X49: Sacos [%] | Y49: 0.53 | Z49: 0.47 | AA49: =+AVERAGE(Z49,AB49) -> 0.45 | AB49: 0.43
C50: Colombia | D50: 69 | E50: 64 | F50: =AVERAGE(E50,G50) -> 59.5 | G50: 55 | M50: FCk Precast | N50: 0.8 | O50: 0.75 | P50: =AVERAGE(O50,Q50) -> 0.71 | Q50: 0.67 | X50: Silos [%] | Y50: 0.07 | Z50: 0.07 | AA50: =AVERAGE(Z50,AB50) -> 0.07 | AB50: 0.07
C51: Chile | D51: 71 | E51: 68 | F51: =AVERAGE(E51,G51) -> 65.5 | G51: 63 | X51: Prefabricados [%] | Y51: 0.05 | Z51: 0.07 | AA51: =AVERAGE(Z51,AB51) -> 0.07 | AB51: 0.07
C52: ARGENTINA | D52: 68 | E52: 65 | F52: =AVERAGE(E52,G52) -> 63 | G52: 61 | M52: MATERIAS PRIMAS CEMENTO | N52: 2020 | O52: 2030 | P52: 2040 | Q52: 2050
C53: GCCA Roadmap | D53: 63 | E53: 58 | F53: =AVERAGE(E53,G53) -> 56 | G53: 54 | M53: Clínker [%] | N53: 0.67 | O53: 0.65 | P53: =+AVERAGE(O53,Q53) -> 0.63 | Q53: 0.61
M54: Yeso [%] | N54: 0.05 | O54: 0.05 | P54: =+AVERAGE(O54,Q54) -> 0.05 | Q54: 0.05
M55: Caliza [%] | N55: 0.17 | O55: 0.15 | P55: =+AVERAGE(O55,Q55) -> 0.175 | Q55: 0.2
M56: Escoria Alto Horno [%] | N56: 0.05 | O56: 0.04 | P56: =+AVERAGE(O56,Q56) -> 0.045 | Q56: 0.05
C57: Pertic | M57: Cenizas Volantes [%] | N57: 0 | O57: 0.02 | P57: =+AVERAGE(O57,Q57) -> 0.01 | Q57: 0
M58: Puzolana Natural [%] | N58: 0.05 | O58: 0.05 | P58: =+AVERAGE(O58,Q58) -> 0.04 | Q58: 0.03
M59: Arcillas Calcinadas [%] | N59: 0.01 | O59: 0.04 | P59: =+AVERAGE(O59,Q59) -> 0.045 | Q59: 0.05
M60: Otras Adiciones [%] | N60: 0 | O60: 0.01 | P60: =+AVERAGE(O60,Q60) -> 0.01 | Q60: 0.01
N63: =+SUM(N53:N60) -> 1 | O63: =+SUM(O53:O60) -> 1.01 | P63: =+SUM(P53:P60) -> 1.005 | Q63: =+SUM(Q53:Q60) -> 1

Sheet Eje 4
B2: EFICIENCIA TERMICA
B4: Este eje depende de varios factores, entre los que se destacan la preparación de materias pimas y combustibles, el aumento en la capacidad de los hornos, el cambio de hornos largos a hornos con 6 etapas y precalcinador y uso de enfriadores de clínker con tecnología eficiente. El promedio global reportado en GNR año 2022 es de 3501 MJ/tclínker.
B7: Actualmente, en LAC, según datos de GNR del año 2022, el 55% de los hornos son de tipo proceso seco, con precalentador y precalcinador, mientras que un 24% de hornos operan con proceso seco, con precalentador y sin precalcinador, un 1% de hornos largos sin precalcinador, 18% de hornos mixtos; y el 2% restante corresponde a hornos verticales con proceso húmedo. Los valores de energía específica se encuentran entre los 3465 MJ/tclínker y los 6405 MJ/tclínker. El promedio en LAC es de 3576 MJ/tclínker.
D44: Eficiencia Térmica | E44: 2020 | F44: 2030 | G44: 2040 | H44: 2050
D45: FICEM | E45: 3.6 | F45: 3.5 | G45: =AVERAGE(F45,H45) -> 3.45 | H45: 3.4
D46: Perú | E46: 3.4 | F46: 3.2 | G46: =AVERAGE(F46,H46) -> 3.15 | H46: 3.1
D47: Colombia | E47: 4.1 | F47: 3.8 | G47: =AVERAGE(F47,H47) -> 3.65 | H47: 3.5
D48: Chile | E48: 3.9 | F48: 3.5 | G48: =AVERAGE(F48,H48) -> 3.4 | H48: 3.3
D49: ARGENTINA | E49: 3.425 | F49: 3.4 | G49: =AVERAGE(F49,H49) -> 3.35 | H49: 3.3

Sheet Eje 5
B2: COMBUSTIBLES FOSILES CONVENCIONALES
B3: Los combustibles fósiles tradicionales utilizados en hornos de cemento son, principalmente, el carbón y los derivados del petróleo. La energía aportada por este tipo de combustibles, corresponde a la suma de la participación de cada uno de ellos. A nivel global, según GNR 2022, los combustibles fósiles tradicionales correspondieron al 77% de la matriz de combustibles, distribuidos de la siguiente manera: carbón, 38%, petcoke 25%, gas natural 10% y el 4% restante, otros combustibles.
B5: Actualmente, el uso de combustibles fósiles es predominante en la industria del cemento, debido a su alta disponibilidad y bajo costo. En la región, el 81% de la matriz de combustibles de la industria cementera corresponde a fósiles tradicionales, distribuidos de la siguiente manera: 49% petcoke, 16% carbón, 14% gas natural y el 2% restante a otros combustibles.
K42: Combustible | L42: 2020 | M42: 2030 | N42: 2040 | O42: 2050
C43: Fosiles Tradicionales | D43: 2020 | E43: 2030 | F43: 2040 | G43: 2050 | K43: Total Fosiles Tradicionales | L43: =+L44+L45 -> 0.93 | M43: =+M44+M45 -> 0.9 | N43: =+N44+N45 -> 0.835 | O43: =+O44+O45 -> 0.77
C44: FICEM | D44: 89 | E44: 75 | F44: =AVERAGE(E44,G44) -> 57.5 | G44: 40 | K44: Gas Natural | L44: 0.82 | M44: 0.82 | N44: =+AVERAGE(M44,O44) -> 0.785 | O44: 0.75
C45: Perú | D45: 100 | E45: 81 | F45: =+AVERAGE(E45,G45) -> 67.5 | G45: 54 | K45: Petcoke | L45: 0.11 | M45: 0.08 | N45: =AVERAGE(M45,O45) -> 0.05 | O45: 0.02
C46: Colombia | D46: 92 | E46: 85 | F46: =AVERAGE(E46,G46) -> 65 | G46: 45 | K46: Carbón
C47: Chile | D47: 85 | E47: 65 | F47: =AVERAGE(E47,G47) -> 43.5 | G47: 22 | K47: Heavy Fuel
C48: ARGENTINA | D48: 93 | E48: 90 | F48: =AVERAGE(E48,G48) -> 83.5 | G48: 77 | K48: Diesel Oil
C49: GCCA Roadmap | D49: 94 | E49: 78 | F49: =AVERAGE(E49,G49) -> 67.5 | G49: 57 | K49: Otros
C51: Carbon
C52: Petcoke
C53: Gas Natural

Sheet Eje Coproc
B2: COPROCESAMIENTO
B3: Corresponden a combustibles cuya energía proviene de la fracción fósil de los residuos. Entre ellos se puede destacar los derivados de residuos urbanos o industriales, neumáticos fuera de uso, plásticos, solventes, aceites usados, entre otros, lo que permite el desplazamiento del uso de combustibles fósiles tradicionales.
B6: El bajo despliegue de este eje, se debe, entre otros factores, a la inadecuada gestión de los residuos en la Región.
B8: Actualmente, la participación de este tipo de combustibles, a nivel regional es de 8%, distribuidos de la siguiente manera: 4% corresponde a residuos industriales y urbanos, 2% a neumáticos fuera de uso, y el 2% restante, a otros combustibles derivados de residuos.
D45: Coprocesamiento | E45: 2020 | F45: 2030 | G45: 2040 | H45: 2050 | J45: Biomasa | K45: 2020 | L45: 2030 | M45: 2040 | N45: 2050 | Q45: Combustible | R45: 2020 | S45: 2030 | T45: 2040 | U45: 2050
D46: FICEM | E46: 11 | F46: 24 | G46: 42.5 | H46: 50 | J46: FICEM | K46: 3 | L46: 4 | M46: =AVERAGE(L46,N46) -> 7 | N46: 10 | Q46: Derivados de Residuos | R46: 0.03 | S46: 0.05 | T46: =+AVERAGE(S46,U46) -> 0.065 | U46: 0.08
D47: Perú | E47: 0 | F47: 19 | G47: 32.5 | H47: 46 | J47: Perú | K47: 0 | L47: 8 | M47: =+AVERAGE(L47,N47) -> 15.5 | N47: 23 | Q47: Residuos Sólidos (RSU/RIS) | R47: 0.01 | S47: 0.02 | T47: =+AVERAGE(S47,U47) -> 0.03 | U47: 0.04
D48: Colombia | E48: 8 | F48: 15 | G48: 35 | H48: 55 | J48: Colombia | K48: 1 | L48: 3 | M48: =AVERAGE(L48,N48) -> 6.5 | N48: 10 | Q48: Neumáticos Fuera de Uso | R48: 0.01 | S48: 0.02 | T48: =AVERAGE(S48,U48) -> 0.025 | U48: 0.03
D49: Chile | E49: 15 | F49: 35 | G49: 56.5 | H49: 78 | J49: Chile | K49: 1 | L49: 7 | M49: =AVERAGE(L49,N49) -> 14.5 | N49: 22 | Q49: Otros Residuos | R49: 0.01 | S49: 0.01 | T49: =+AVERAGE(S49,U49) -> 0.02 | U49: 0.03
D50: ARGENTINA | E50: 5 | F50: 10 | G50: =AVERAGE(F50,H50) -> 14 | H50: 18 | J50: Argentina | K50: 3 | L50: 5 | M50: =AVERAGE(L50,N50) -> 7.5 | N50: 10
D51: GCCA Roadmap | E51: 6 | F51: 22 | G51: =+AVERAGE(F51,H51) -> 32.5 | H51: 43 | K51: =+K50+E50 -> 8 | L51: =+L50+F50 -> 15 | M51: =+M50+G50 -> 21.5 | N51: =+N50+H50 -> 28 | Q51: grafico 2 local biomasa + cdr y coproc

Sheet Eje 6
B2: COMBUSTIBLES FOSILES ALTERNATIVOS
B3: Corresponden a combustibles cuya energía proviene de la fracción fósil de los residuos. Entre ellos se puede destacar los derivados de residuos urbanos o industriales, neumáticos fuera de uso, plásticos, solventes, aceites usados, entre otros, lo que permite el desplazamiento del uso de combustibles fósiles tradicionales.
B6: El bajo despliegue de este eje, se debe, entre otros factores, a la inadecuada gestión de los residuos en la Región.
B8: Actualmente, la participación de este tipo de combustibles, a nivel regional es de 8%, distribuidos de la siguiente manera: 4% corresponde a residuos industriales y urbanos, 2% a neumáticos fuera de uso, y el 2% restante, a otros combustibles derivados de residuos.
D45: CDR Fosiles | E45: 2020 | F45: 2030 | G45: 2040 | H45: 2050 | J45: Biomasa | K45: 2020 | L45: 2030 | M45: 2040 | N45: 2050 | Q45: Combustible | R45: 2020 | S45: 2030 | T45: 2040 | U45: 2050
D46: FICEM | E46: 8 | F46: 20 | G46: =+AVERAGE(F46,H46) -> 30 | H46: 40 | J46: FICEM | K46: 3 | L46: 4 | M46: =AVERAGE(L46,N46) -> 7 | N46: 10 | Q46: Derivados de Residuos | R46: 0.03 | S46: 0.05 | T46: =+AVERAGE(S46,U46) -> 0.065 | U46: 0.08
D47: Perú | E47: 0 | F47: 4 | G47: =+AVERAGE(F47,H47) -> 11 | H47: 18 | J47: Perú | K47: 0 | L47: 8 | M47: =+AVERAGE(L47,N47) -> 15.5 | N47: 23 | Q47: Residuos Sólidos (RSU/RIS) | R47: 0.01 | S47: 0.02 | T47: =+AVERAGE(S47,U47) -> 0.03 | U47: 0.04
D48: Colombia | E48: 7 | F48: 12 | G48: =+AVERAGE(F48,H48) -> 26 | H48: 40 | J48: Colombia | K48: 1 | L48: 3 | M48: =AVERAGE(L48,N48) -> 6.5 | N48: 10 | Q48: Neumáticos Fuera de Uso | R48: 0.01 | S48: 0.02 | T48: 0.02 | U48: 0.02
D49: Chile | E49: 14 | F49: 23 | G49: =+AVERAGE(F49,H49) -> 33 | H49: 43 | J49: Chile | K49: 1 | L49: 7 | M49: =AVERAGE(L49,N49) -> 14.5 | N49: 22 | Q49: Otros Residuos | R49: 0.01 | S49: 0.01 | T49: =+AVERAGE(S49,U49) -> 0.015 | U49: 0.02
D50: ARGENTINA | E50: 3 | F50: 5 | G50: 7 | H50: 8 | J50: Argentina | K50: 3 | L50: 5 | M50: =AVERAGE(L50,N50) -> 7.5 | N50: 10 | Q50: Waste oil
K51: =+K50+E50 -> 6 | L51: =+L50+F50 -> 10 | M51: =+M50+G50 -> 14.5 | N51: =+N50+H50 -> 18 | Q51: RDF (incl. Plasticos)
Q52: Solventes

Sheet Eje 7
C2: COMBUSTIBLES DERIVADOS DE BIOMASA
C38: Biomasa | D38: 2020 | E38: 2030 | F38: 2040 | G38: 2050 | N38: Combustible | O38: 2020 | P38: 2030 | Q38: 2040 | R38: 2050
C39: FICEM | D39: 3 | E39: 4 | F39: =AVERAGE(E39,G39) -> 7 | G39: 10 | N39: Derivados de Biomasa | O39: 0.04 | P39: 0.05 | Q39: =+AVERAGE(P39,R39) -> 0.075 | R39: 0.1
C40: Perú | D40: 0 | E40: 8 | F40: =+AVERAGE(E40,G40) -> 15.5 | G40: 23 | N40: Residuos Agrícolas | O40: 0.03 | P40: 0.04 | Q40: 0.05 | R40: 0.07
C41: Colombia | D41: 1 | E41: 3 | F41: =AVERAGE(E41,G41) -> 6.5 | G41: 10 | N41: Maderas | O41: 0 | P41: 0 | Q41: 0.01 | R41: 0.01
C42: Chile | D42: 1 | E42: 7 | F42: =AVERAGE(E42,G42) -> 14.5 | G42: 22 | N42: Otros Residuos Biomasa | O42: 0.01 | P42: 0.01 | Q42: 0.02 | R42: 0.02
C43: ARGENTINA | D43: 4 | E43: 5 | F43: =AVERAGE(E43,G43) -> 7.5 | G43: 10 | N43: Lodos
N44: Papeles, cartones

Sheet Eje 8
C2: COMBUSTIBLES DE HIDROGENO BAJO EN CARBONO
P17: MATRIZ COMBUSTIBLES | Q17: 2020 | R17: 2030 | S17: 2040 | T17: 2050
P18: Fósiles Tradicionales | Q18: 0.93 | R18: 0.9 | S18: =+AVERAGE(R18,T18) -> 0.835 | T18: 0.77
P19: Derivados Residuos Fósiles | Q19: 0.03 | R19: 0.05 | S19: =+AVERAGE(R19,T19) -> 0.065 | T19: 0.08
P20: Biomasa | Q20: 0.04 | R20: 0.05 | S20: =+AVERAGE(R20,T20) -> 0.075 | T20: 0.1
P21: Hidrógeno | Q21: 0 | R21: 0 | S21: 0.01 | T21: 0.05
P22: Energia Producción H2 (MWh/tH2) | Q22: 44 | R22: 44 | S22: 44 | T22: 44
P23: Poder Calorífico (MJ/kgH2) | Q23: 120 | R23: 120 | S23: 120 | T23: 120
C38: Coprocesamiento | D38: 2020 | E38: 2030 | F38: 2040 | G38: 2050
C39: FICEM | D39: 0 | E39: 1 | F39: =AVERAGE(E39,G39) -> 5.5 | G39: 10
C40: Perú | D40: 0 | E40: 0 | F40: =+AVERAGE(E40,G40) -> 0.5 | G40: 1
C41: Colombia | D41: 1 | E41: 3 | F41: =AVERAGE(E41,G41) -> 6.5 | G41: 10
C42: Chile | D42: 0 | E42: 2 | F42: =AVERAGE(E42,G42) -> 6 | G42: 10
C43: Argentina | D43: 0 | E43: 0 | F43: =AVERAGE(E43,G43) -> 2.5 | G43: 5
C44: Global GNR

Sheet Eje 9-10-11
C2: COMBUSTIBLES DE HIDROGENO BAJO EN CARBONO
C38: 2050 | D38: CCUS | E38: Metano | F38: SbN | G38: total
C39: FICEM | D39: 30 | E39: 3 | F39: 9 | G39: =+SUM(D39:F39) -> 42
C40: Argentina | D40: 19 | E40: 10 | F40: 13 | G40: =+SUM(D40:F40) -> 42
C41: Perú | D41: 20 | E41: 9 | F41: 11 | G41: =+SUM(D41:F41) -> 40 | L41: =2.5*0.33 -> 0.825 | N41: =8.3*0.33 -> 2.739
C42: GCCA | D42: 36 | E42: 0 | F42: 0 | G42: =+SUM(D42:F42) -> 36 | L42: =+L41/3.8 -> 0.21710526 | N42: =+N41/16.9 -> 0.16207101
C43: Colombia | D43: 16 | E43: 4 | F43: 13 | G43: =+SUM(D43:F43) -> 33
C44: Chile | D44: 22 | E44: 2 | F44: 9 | G44: =+SUM(D44:F44) -> 33
C45: Cembureau | D45: 42
C46: India
C47: China | D47: 30
C48: Canada | D48: 57
D49: Ejes 12-13 | E49: CCUS
S53: RECARBONATACION | U53: 2020 | V53: 2030 | W53: 2040 | X53: 2050
S54: Factor Recarbonatación | T54: % | U54: 0.2 | V54: 0.2 | W54: 0.2 | X54: 0.2
S55: Factor Emisión Calcinación | T55: kgCO2/kgCk | U55: 0.525 | V55: 0.525 | W55: 0.525 | X55: 0.525
S56: Volumen Producción Clínker | T56: MtCk | U56: 8.5 | V56: 9.2 | W56: =+AVERAGE(V56,X56) -> 9.85 | X56: 10.5
S57: Sumidero de Emsiones | T57: MtCO2 | U57: =+U54*U55*U56 -> 0.8925 | V57: =+V54*V55*V56 -> 0.966 | W57: =+W54*W55*W56 -> 1.03425 | X57: =+X54*X55*X56 -> 1.1025

Sheet CCUS
B38: 2050 | D38: CCUS | E38: SbN | F38: Metano | G38: Total | H38: FCk | I38: Coproces
B39: India* | D39: 0.25 | G39: =SUM(D39:F39) -> 0.25 | H39: 0.56 | I39: 0.5
B40: China | D40: 0.3 | G40: =SUM(D40:F40) -> 0.3 | H40: 0.65 | I40: 0.53
B41: Chile | D41: 0.22 | E41: 0.02 | F41: 0.09 | G41: =SUM(D41:F41) -> 0.33 | H41: 0.63 | I41: 0.66
B42: Colombia | D42: 0.16 | E42: 0.04 | F42: 0.13 | G42: =SUM(D42:F42) -> 0.33 | H42: 0.55 | I42: 0.5
B43: GCCA | D43: 0.36 | G43: =SUM(D43:F43) -> 0.36 | H43: 0.54 | I43: 0.43
B44: Perú | D44: 0.2 | E44: 0.09 | F44: 0.11 | G44: =SUM(D44:F44) -> 0.4 | H44: 0.63 | I44: 0.45
B45: FICEM | D45: 0.3 | E45: 0.03 | F45: 0.09 | G45: =SUM(D45:F45) -> 0.42 | H45: 0.6 | I45: 0.5
B46: Cembureau | D46: 0.42 | G46: =SUM(D46:F46) -> 0.42 | H46: 0.65 | I46: 0.9
B47: Argentina | D47: 0.19 | E47: 0.1 | F47: 0.13 | G47: =SUM(D47:F47) -> 0.42 | H47: 0.61 | I47: 0.18
D49: Ejes 12-13 | E49: CCUS
S53: RECARBONATACION | U53: 2020 | V53: 2030 | W53: 2040 | X53: 2050
S54: Factor Recarbonatación | T54: % | U54: 0.2 | V54: 0.2 | W54: 0.2 | X54: 0.2
S55: Factor Emisión Calcinación | T55: kgCO2/kgCk | U55: 0.525 | V55: 0.525 | W55: 0.525 | X55: 0.525
S56: Volumen Producción Clínker | T56: MtCk | U56: 8.5 | V56: 9.2 | W56: =+AVERAGE(V56,X56) -> 9.85 | X56: 10.5
S57: Sumidero de Emsiones | T57: MtCO2 | U57: =+U54*U55*U56 -> 0.8925 | V57: =+V54*V55*V56 -> 0.966 | W57: =+W54*W55*W56 -> 1.03425 | X57: =+X54*X55*X56 -> 1.1025

Sheet Resumen Ejes de Reduccion
B2: ROADMAP NZA GCCA-FICEM ARGENTINA 2050
E3: 2023 | F3: 0.18 | G3: 0.55
E4: 2020 | F4: 2030 | G4: 2050 | H4: baja demanda | I4: alta demanda
B5: PRINCIPALES INDICADORES | C5: Cemento BAU | D5: Mt | E5: =+'Whole life model'!F17 -> 12.55 | F5: =+E5*(1+F3) -> 14.809 | G5: =+E5*(1+G3) -> 19.4525 | H5: 2030: 10% a 20% 2050: 25% a 40% | I5: 2030: 25% a 40% 2050: 50% a 80%
C6: Cemento NZA | D6: Mt | E6: =+'Whole life model'!F21 -> 12.55 | F6: =+'Whole life model'!G21 -> 14.141428 | G6: =+'Whole life model'!H21 -> 16.913329 | I6: 1 | J6: LB 2020 Ck | K6: =+E25 -> 6.3131988
C7: Emisiones Brutas Cemento | D7: kg CO2/t cement | E7: =+E17/E6*1000 -> 503.04373 | F7: =+F17/F5*1000 -> 490.8808 | G7: =+G17/G5*1000 -> 485.50488 | J7: Alc2 | K7: =+E28 -> 0.42105302
C8: Emisiones Netas Cemento | D8: kg CO2/t cement | E8: =+E7-1000*(E112*E113*E119)/1000000 -> 494.82373 | F8: =+F7-1000*(F112*F113*F119)/1000000 -> 476.8808 | G8: =+G7-1000*(G112*G113*G119)/1000000 -> 464.38488 | J8: Total 2020 | K8: =+K6+K7 -> 6.7342518
C9: Clinker BAU | D9: Mt | E9: =+E11*E5 -> 8.47125 | F9: =+F11*F5 -> 9.6836051 | G9: =+E9*(1+G3) -> 13.130438 | J9: Aumento 2050 | K9: =+G19 -> 1.55
C10: Clinker NZA | D10: Mt | E10: =+E6*E11 -> 8.47125 | F10: =+F6*F11 -> 9.24708 | G10: =+G6*G11 -> 10.358906 | H10: 0.2 | J10: BAU 2050 | K10: =+K8*K9 -> 10.43809
C11: Factor Clinker NZA | D11: % | E11: 0.675 | F11: =+F32*F33+F37*F38+F42*F43+F47*F48 -> 0.6539 | G11: =+G32*G33+G37*G38+G42*G43+G47*G48 -> 0.61247 | H11: =+H10/H12 -> 0.01980198
C12: Coprocesamiento NZA | D12: % | E12: =+E111 -> 0.07 | F12: =+F111 -> 0.1 | G12: =+G111 -> 0.18 | H12: =6.1+0.4+3.6 -> 10.1 | I12: 2 | J12: D&C (13%) | K12: =-G54 -> -1.0078503 | L12: =K10+K10*M12 -> 9.43024 | M12: =-H54 -> -0.09655505 | N12: =+K10+K12 -> 9.43024
C13: Biomasa | D13: % | E13: =+E114 -> 0.04 | F13: =+F114 -> 0.05 | G13: =+G114 -> 0.1 | I13: =+I12+1 -> 3 | J13: Concreto (7%) | K13: =+L12-L13 -> -0.63594932 | L13: =+L12-K10*M13 -> 10.066189 | M13: =-H55 -> -0.06092583 | N13: =+N12+K13 -> 8.7942907
C14: Consumo Térmico | D14: MJ/t clinker | E14: 3425 | F14: 3400 | G14: 3300 | I14: =+I13+1 -> 4 | J14: Cem&Adic (7%) | K14: =+L13-L14 -> -0.85273514 | L14: =+L13-K$10*M14 -> 10.918924 | M14: =-H68-H74 -> -0.081694555 | N14: =+N13+K14 -> 7.9415555
C15: Consumo de Concreto | D15: Mm3 | E15: =+'Whole life model'!N49*1000 -> 32.9 | F15: =+'Whole life model'!O49*1000 -> 37.5 | G15: =+'Whole life model'!P49*1000 -> 50.5 | H15: Clinker (15,5%) | I15: =+I14+1 -> 5 | J15: Efic. Term (2%) | K15: =+L14-L15 -> -0.053832098 | L15: =+L14-K$10*M15 -> 10.972757 | M15: =-L28 -> -0.0051572746
C16: Cemento en el Concreto | D16: kgcem/m3 | E16: =+E6/E15*1000 -> 381.45897 | F16: =+F6/F15*1000 -> 377.10476 | G16: =+G6/G15*1000 -> 334.9174 | I16: =+I15+1 -> 6 | J16: Fosil Conv (3%) | K16: =+L15-L16 -> -0.083439752 | L16: =+L15-K$10*M16 -> 11.056196 | M16: =-L29 -> -0.0079937757
C17: Emisiones Directas (Calcinación + Comb. Fósiles) | D17: Mt | E17: =+E9*E21/1000 -> 6.3131988 | F17: =+F9*F21/1000 -> 7.2694537 | G17: =+G9*G21/1000 -> 9.4442836 | H17: =+G10*G21/1000 -> 7.4508141 | I17: =+I16+1 -> 7 | J17: Fosil Alt (2%) | K17: =+L16-L17 -> -0.2187801 | L17: =+L16-K$10*M17 -> 11.274976 | M17: =-H120 -> -0.020959782
C18: Emisiones Residuales (sin CCUS) | D18: Mt | E18: =+E131 -> 5.3540839 | F18: =+F131 -> 6.1690512 | G18: =+G131 -> 5.5301906 | I18: =+I17+1 -> 8 | J18: Biom (5%) | K18: =+L17-L18 -> -0.12112222 | L18: =+L17-K$10*M18 -> 11.396099 | M18: =-L30 -> -0.011603868
C19: Aumento Demanda | D19: % | E19: 0 | F19: =1+F3 -> 1.18 | G19: =1+G3 -> 1.55 | I19: =+I21+1 -> 11 | J19: Metano (5%) | K19: =+L21-L19 -> -0.5174967 | L19: =+L21-K$10*M19 -> 14.194362 | M19: =-H133 -> -0.049577718
C20: Indicador | D20: Unidad | E20: 2020 | F20: 2030 | G20: 2050 | I20: =+I18+1 -> 9 | J20: H2V (0,5%) | K20: =+L18-L20 -> -0.01076642 | L20: =+L18-K$10*M20 -> 11.406865 | M20: =-L31 -> -0.0010314549
C21: Factor de Emisión Clínker Ponderado | D21: kg CO2/t clinker | E21: =+(E22*(1-E24)+E24*E23) -> 745.24997 | F21: =+(F22*(1-F24)+F24*F23) -> 750.69705 | G21: =+(G22*(1-G24)+G24*G23) -> 719.26648 | I21: =+I20+1 -> 10 | J21: CCUS (21%) | K21: =+L20-L21 -> -2.27 | L21: =+L20-K$10*M21 -> 13.676865 | M21: =-H132 -> -0.21747273 | O21: a | P21: 19
C22: FE Clínker Local Bruta | D22: kg CO2/t clinker | E22: =+E95 -> 745.24997 | F22: =+F95 -> 750.69705 | G22: =+G95 -> 719.26648 | I22: =+I24+1 -> 14 | J22: SbN (21%) | K22: =+L24-L22 -> -2.27 | L22: =+L24-K$10*M22 -> 18.157456 | M22: =-H134 -> -0.21747273 | O22: b | P22: 23
C23: FE Clínker Importado Bruta | D23: kg CO2/t clinker | E23: =+E99 -> 865 | F23: =+F99 -> 865 | G23: =+G99 -> 865 | I23: =+I19+1 -> 12 | J23: Electr (7%) | K23: =+L19-L23 -> -0.60540924 | L23: =+L19-K$10*M23 -> 14.799771 | M23: -0.058 | O23: c | P23: 41
C24: Participación Clínker Importado | D24: % | E24: =+E96 -> 0 | F24: 0 | G24: 0 | I24: =+I23+1 -> 13 | J24: Recarb (12%) | K24: =+L23-L24 -> -1.0876852 | L24: =+L23-K$10*M24 -> 15.887456 | M24: =-H125 -> -0.10420346 | O24: d | P24: 7
C25: Emisiones Clínker 2020 | D25: Mt CO2 | E25: =+E21*E9/1000 -> 6.3131988 | F25: =+F21*F9/1000 -> 7.2694537 | G25: =+G21*G9/1000 -> 9.4442836 | J25: =13+7+7+15.5+7+12 -> 61.5 | M25: =+SUM(M12:M24) -> -0.93264823 | O25: e | P25: 10
C26: Factor Eléctrico | D26: [g CO2/kWh] | E26: =+E76 -> 272.4 | F26: =+F76 -> 200 | G26: =+G76 -> 14.1 | J26: =100-J25 -> 38.5
C27: Consumo eléctrico Total | D27: TWh | E27: =+E78+E80+E82 -> 1.5457159 | F27: =+F78+F80+F82 -> 1.6773572 | G27: =+G78+G80+G82 -> 3.712892 | K27: =+K15+K16+K18+K20 -> -0.26916049 | M27: =+M16+M18+M15+M20 -> -0.025786373
C28: Emisiones Eléctricas | D28: Mt CO2 | E28: =+E26*E27/1000 -> 0.42105302 | F28: =+F26*F27/1000 -> 0.33547143 | G28: =+G26*G27/1000 -> 0.052351777 | J28: 20 | K28: E. Termica | L28: =+J28*H$102/100 -> 0.0051572746
B29: EMISIONES TOTALES DE CO2 LINEA BASE 2020 (LINEA BASE) | D29: Mt CO2 | E29: =+E25+E28 -> 6.7342518 | F29: =+F25+F28 -> 7.6049252 | G29: =+G25+G28 -> 9.4966354 | J29: 31 | K29: Fosil Conv | L29: =+J29*H$102/100 -> 0.0079937757
B30: AUMENTO EMISIONES POR DEMANDA SOCIAL 2050 (EJE 1) | D30: Mt CO2 | E30: N/A | F30: =+F17 -> 7.2694537 | G30: =+E29*(G19-1) -> 3.7038385 | H30: =+E29*(1+G3) -> 10.43809 | J30: 45 | K30: Biomasa | L30: =+J30*H$102/100 -> 0.011603868
E31: 2022 | F31: 2030 | G31: 2050 | I31: =+(G32-E32)/E32 -> 0.21813031 | J31: 4 | K31: H2V | L31: =+J31*H$102/100 -> 0.0010314549
B32: CANALES | C32: Concreto Premezclado | D32: % | E32: 0.353 | F32: 0.39 | G32: 0.43 | H32: =+E32*E33+E37*E38+E42*E43+E47*E48 -> 0.678048 | I32: =+(G33-E33)/E33 -> -0.11025641 | J32: =+SUM(J28:J31) -> 100 | L32: =+SUM(L28:L31) -> 0.025786373
C33: Factor clínker | D33: % | E33: 0.78 | F33: 0.75 | G33: 0.694 | H33: =+F32*F33+F37*F38+F42*F43+F47*F48 -> 0.6539 | J33: =+E32+E37+E42+E47 -> 1.01
C34: Infraestructura | D34: % | E34: 0.5 | F34: 0.5 | G34: 0.5 | H34: =+G32*G33+G37*G38+G42*G43+G47*G48 -> 0.61247 | J34: =+F32+F37+F42+F47 -> 1
C35: Construcción Estructural | D35: % | E35: 0.5 | F35: 0.5 | G35: 0.5 | J35: =+G32+G37+G42+G47 -> 0.995
C36: Construcción No Estructural | D36: % | E36: 0 | F36: =100%-F34-F35 -> 0 | G36: =100%-G34-G35 -> 0 | I36: =+(G37-E37)/E37 -> -0.19172932
C37: Sacos | D37: % | E37: 0.532 | F37: 0.47 | G37: 0.43 | I37: =+(G38-E38)/E38 -> -0.094076655 | AD37: =5.5/(6.3+0.3+3.36) -> 0.55220884
C38: Factor clínker | D38: % | E38: 0.574 | F38: 0.55 | G38: 0.52
C39: Infraestructura | D39: % | E39: 0.2 | F39: 0.2 | G39: 0.2
C40: Estructural | D40: % | E40: 0.4 | F40: 0.4 | G40: 0.4
C41: No Estructural | D41: % | E41: =100%-E39-E40 -> 0.4 | F41: =100%-F39-F40 -> 0.4 | G41: =100%-G39-G40 -> 0.4
...

Sheet Whole life model
E1: Reference | F1: CEMENT FOR DOMESTIC USE | J1: Select world region for GCCA Roadmap: | P1: Colour index: | V1: Market segments | W1: README information
E2: Region | F2: ARGENTINA | J2: North America (Canada/USA) PCA/CAC | M2: Europe (Cembureau, ERMCO, BIBM) | P2: text information and descriptions | R2: default starting values, do not change
E3: Organisation | F3: AFCP | J3: Central + South America (Ficem) | M3: CIS Countries | P3: start with cement volumes | R3: Value from other worksheet
E4: corresponding author | F4: FICEM and AFCP | J4: China (CNBM) | M4: Africa (Dangote) | P4: then fill in all parts in green | R4: Calculated automatically | W4: Numbers to be filled in have been pre-set, for sake of easy reading. Please change!
E5: E-mail contact | F5: maria.lefevre@afcp.org.ar | J5: India (GCCA India) | M5: Middle East | P5: instruction text in italics, further README information at the right side | W5: Numbers only filled in for example of RMX
E6: Phone contact | F6: Phone | J6: Asia (incl. Japan, S.Korea, SE Asia, Oceania, excl. China and India)
B7: GCCA Roadmap Template | D7: Version 202, 19.07.2022, ECRA | E7: Reference year | F7: 2020 | G7: 2030 | H7: 2050 | J7: =F7 -> 2020 | K7: =G7 -> 2030 | L7: =H7 -> 2050 | M7: =F7 -> 2020 | N7: =G7 -> 2030 | O7: =H7 -> 2050 | P7: =F7 -> 2020 | Q7: =G7 -> 2030 | R7: =H7 -> 2050 | S7: =F7 -> 2020 | T7: =G7 -> 2030 | U7: =H7 -> 2050 | W7: Enter absolute values in volumes per one year, 2020 reference is assessed based on 2018 data
B8: Index | C8: Section | D8: Description | E8: Unit | G8: Summary | K8: Readymix | N8: (Concrete, mortar, screed from ) Bagged Cement | Q8: (Mortar, screed, others) Project Site Silos | T8: Precast (all factory produced product) | W8: Cement end use segment
B9: 0 | C9: Society demand
B10: 0.1 | D10: Crecimiento/disminución del mercado de la construcción* (desarrollo de la demanda social externa) | E10: % vs. status quo | F10: 1 | G10: =+'Resumen Ejes de Reduccion'!F3+1 -> 1.18 | H10: =+'Resumen Ejes de Reduccion'!G3+1 -> 1.55 | W10: The relative numbers of society demand shall allow for growth and efficiency effects, i.e. effects of rising population, urbanisation, development etc. AND decline due to re-use of buildings, higher utilisation, etc. For your estimate you can also use additional information from sources suggested on the sheet 'Info Society demand'
B11: 0.2 | D11: Cuota de segmentos de mercado de la producción de hormigón | E11: % | F11: =IF((J11+M11+S11+P11)=1,(J11+M11+S11+P11), "different from 100%, please correct line 0.2.5") -> 1 | G11: =IF((K11+N11+T11+Q11)=1,(K11+N11+T11+Q11), "different from 100%, please correct line 0.2.5") -> 1 | H11: =IF((L11+O11+U11+R11)=1,(L11+O11+U11+R11), "different from 100%, please correct line 0.2.5") -> 1 | J11: =J17/$F$17 -> 0.35258964 | K11: =+'0.2 Share of concrete'!G16 -> 0.39 | L11: =+'0.2 Share of concrete'!H16 -> 0.43 | M11: =M17/$F$17 -> 0.52788845 | N11: =+'0.2 Share of concrete'!J16 -> 0.47 | O11: =+'0.2 Share of concrete'!K16 -> 0.43 | P11: =P17/$F$17 -> 0.069721116 | Q11: =+'0.2 Share of concrete'!M16 -> 0.07 | R11: =+'0.2 Share of concrete'!N16 -> 0.07 | S11: =S17/$F$17 -> 0.049800797 | T11: =+'0.2 Share of concrete'!P16 -> 0.07 | U11: =+'0.2 Share of concrete'!Q16 -> 0.07 | W11: Value taken from sheet "0.2 Share of concrete".
B12: 4 | C12: Design & Construction
B13: 4.1 | D13: Ganancia de eficiencia (intensidad de material) por diseño y construcción | E13: % vs. status quo | F13: =(J17*F10/F10*J11/J11*J15/J15*J13/J13+M17*F10/F10*M11/M11*M15/M15*M13/M13+P17*F10/F10*P11/P11*P15/P15*P13/P13+S17*F10/F10*S11/S11*S15/S15*S13/S13)/(F17*F10/F10*F15/F15) -> 1 | G13: =(J17*G10/F10*K11/J11*K15/J15*K13/J13+M17*G10/F10*N11/M11*N15/M15*N13/M13+P17*G10/F10*Q11/P11*Q15/P15*Q13/P13+S17*G10/F10*T11/S11*T15/S15*T13/S13)/(F17*G10/F10*G15/F15) -> 0.95585318 | H13: =(J17*H10/F10*L11/J11*L15/J15*L13/J13+M17*H10/F10*O11/M11*O15/M15*O13/M13+P17*H10/F10*R11/P11*R15/P15*R13/P13+S17*H10/F10*U11/S11*U15/S15*U13/S13)/(F17*H10/F10*H15/F15) -> 0.91781397 | I13: =+F13-H13 -> 0.082186034 | J13: 1 | K13: ='4.1 Design & Construction'!K44 -> 0.94111875 | L13: ='4.1 Design & Construction'!W44 -> 0.92169 | M13: 1 | N13: ='4.1 Design & Construction'!N44 -> 0.96525 | O13: ='4.1 Design & Construction'!Z44 -> 0.910518 | P13: 1 | Q13: ='4.1 Design & Construction'!Q44 -> 0.96525 | R13: ='4.1 Design & Construction'!AC44 -> 0.92169 | S13: 1 | T13: ='4.1 Design & Construction'!T44 -> 0.96525 | U13: ='4.1 Design & Construction'!AF44 -> 0.931 | W13: Value taken from sheet "4.1 Desing and construction". The unit for efficiency expressed as % cement saving, signficant design and construction efficiencies can be converted to a relative cement saving in %
B14: 3 | C14: Concrete
B15: 3.1 | D15: Ganancias de eficiencia (intensidad material) en la producción de concreto (excluyendo SCM) | E15: % vs. status quo | F15: =(J17*F10/F10*J11/J11*J15/J15+M17*F10/F10*M11/M11*M15/M15+P17*F10/F10*P11/P11*P15/P15+S17*F10/F10*S11/S11*S15/S15)/(F17*F10/F10) -> 1 | G15: =(J17*G10/F10*K11/J11*K15/J15+M17*G10/F10*N11/M11*N15/M15+P17*G10/F10*Q11/P11*Q15/P15+S17*G10/F10*T11/S11*T15/S15)/(F17*G10/F10) -> 0.999025 | H15: =(J17*H10/F10*L11/J11*L15/J15+M17*H10/F10*O11/M11*O15/M15+P17*H10/F10*R11/P11*R15/P15+S17*H10/F10*U11/S11*U15/S15)/(F17*H10/F10) -> 0.947325 | I15: =+F15-H15 -> 0.052675 | J15: 1 | K15: ='3.1 Concrete production'!G24 -> 0.9975 | L15: ='3.1 Concrete production'!H24 -> 0.9775 | M15: 1 | N15: ='3.1 Concrete production'!J24 -> 1 | O15: ='3.1 Concrete production'!K24 -> 0.9 | P15: 1 | Q15: ='3.1 Concrete production'!M24 -> 1 | R15: ='3.1 Concrete production'!N24 -> 1 | S15: 1 | T15: ='3.1 Concrete production'!P24 -> 1 | U15: ='3.1 Concrete production'!Q24 -> 1 | W15: Value taken from sheet "3.1 Concrete production". The unit for efficiency expressed as % cement saving, signficant efficiency gains in concrete production and shift between product categories can be converted to a relative cement saving in %
B16: 2 | C16: Cement & Binders | F16: BAU | G16: =+F17*G10 -> 14.809 | H16: =+F17*H10 -> 19.4525
B17: 2.1 | D17: Volumen de ligante en hormigón (material cementoso, cemento y SCM en planta de hormigón) | E17: Mt cementitious | F17: =J17+M17+P17++S17 -> 12.55 | G17: =K17+N17+Q17+T17 -> 14.141428 | H17: =L17+O17+R17++U17 -> 16.913329 | J17: =J21+J18 -> 4.425 | K17: =+J17*G10/$F$10*K13/$J$13*K15/$J$15*K11/$J$11 -> 5.4218521 | L17: =+J17*H10/$F$10*L13/$J$13*L15/$J$15*L11/$J$11 -> 7.5360804 | M17: =M21+M18 -> 6.625 | N17: =+M17*G10/$F$10*N13/$M$13*N15/$M$15*N11/$M$11 -> 6.718362 | O17: =+M17*H10/$F$10*O13/$M$13*O15/$M$15*O11/$M$11 -> 6.8544865 | P17: =P21+P18 -> 0.875 | Q17: =+P17*G10/$F$10*Q13/$P$13*Q15/$P$15*Q11/$P$11 -> 1.0006071 | R17: =+P17*H10/$F$10*R13/$P$13*R15/$P$15*R11/$P$11 -> 1.2550422 | S17: =S21+S18 -> 0.625 | T17: =+S17*G10/$F$10*T13/$S$13*T15/$S$15*T11/$S$11 -> 1.0006071 | U17: =+S17*H10/$F$10*U13/$S$13*U15/$S$15*U11/$S$11 -> 1.2677194 | W17: Value determined from cement volume (line 2.4.1) considering society demand changes and efficiency changes in design & construction and concrete production
B18: 2.2 | D18: Uso de materiales cementicios suplementarios (SCM) en la producción de hormigón | E18: Mt cementitious | F18: =J18+M18+P18++S18 -> 0 | G18: =K18+N18+Q18++T18 -> 0 | H18: =L18+O18+R18++U18 -> 0 | J18: 0 | K18: 0 | L18: 0 | M18: 0 | N18: 0 | O18: 0 | P18: 0 | Q18: 0 | R18: 0 | S18: 0 | T18: 0 | U18: 0 | W18: The use of supplementary cementitious materials (SCM) in concrete production is recorded in Mt of SCM. Note that the use of SCM in cement production is already reflected by changes in the clinker factor (line 2.4.2) and can be descirbed in the corresponding extra sheet.
B19: 2.3 | D19: "Factor aglomerante de clinker en el hormigón" que refleja el uso adicional de SCM en la producción de hormigón (comparable con IEA ETP, el enfoque de Cembureau) | E19: kg clinker/kg cementitious | F19: =F24/F17 -> 0.66944223 | G19: =G24/G17 -> 0.65286055 | H19: =H24/H17 -> 0.61812072 | J19: =IF(J17=0,"not available",J24/J17) -> 0.78 | K19: =IF(K17=0,"not available",K24/K17) -> 0.75 | L19: =IF(L17=0,"not available",L24/L17) -> 0.69 | M19: =IF(M17=0,"not available",M24/M17) -> 0.57 | N19: =IF(N17=0,"not available",N24/N17) -> 0.55 | O19: =IF(O17=0,"not available",O24/O17) -> 0.52 | P19: =IF(P17=0,"not available",P24/P17) -> 0.77 | Q19: =IF(Q17=0,"not available",Q24/Q17) -> 0.72 | ... U19: =IF(U17=0,"not available",U24/U17) -> 0.67 | W19: This clincker binder factor encompasses the change in SCM use in concrete in 2030 and 2050. It is used to jointly illustrate CO2 mitigation in cement & binders due to (i) changes in cement production (clinker factor) and (ii) changes in SCM use in concrete.
B20: 2.4 | C20: Cement | J20: =+J21+M21+P21+S21 -> 12.55
B21: 2.4.1 | D21: Volumen de producción de cemento (excl. SCM para uso en planta de concreto) | E21: Mt cement | F21: =J21+M21+P21+S21 -> 12.55 | G21: =K21+N21+Q21+T21 -> 14.141428 | H21: =L21+O21+R21+U21 -> 16.913329 | J21: =12.5*0.354 -> 4.425 | K21: =(+K17-K18) -> 5.4218521 | L21: =+L17-L18 -> 7.5360804 | M21: =12.5*0.53 -> 6.625 | N21: =(+N17-N18) -> 6.718362 | O21: =+O17-O18 -> 6.8544865 | P21: =12.5*0.07 -> 0.875 | Q21: =(+Q17-Q18) -> 1.0006071 | R21: =+R17-R18 -> 1.2550422 | S21: =12.5*0.05 -> 0.625 | T21: =(+T17-T18) -> 1.0006071 | U21: =+U17-U18 -> 1.2677194 | W21: Start the calculation with 2020 cement production volumes in four categories Readymix, Bagged Cement, Mortar and Precast. As 2020 statistics are not yet known, 2018 statistical data on cement production can be used as substitute and assuming similar production for 2020. Changes in SCM use in cement production shall be reflected in the production volume (line 2.4.1), the clinker factor (line 2.4.2) together with a brief description in the sheet "2.2 & 2.4.2 Cement & Binder". Future changes to SCM use in concrete production are recorded in line 2.2.
B22: 2.4.2 | D22: Clinker factor | E22: kg clinker/kg cement | F22: =F24/F21 -> 0.66944223 | G22: =G24/G21 -> 0.65286055 | H22: =H24/H21 -> 0.61812072 | J22: 0.78 | K22: 0.75 | L22: 0.69 | M22: 0.57 | N22: 0.55 | O22: 0.52 | P22: 0.77 | Q22: 0.72 | R22: 0.67 | S22: 0.8 | T22: 0.75 | U22: 0.67 | W22: Value reflecting the status quo 2020 (or 2018 statistics) and 2030 and 2050 development of the efficient use of clinker in cement production. Please record the description and relevance of related technologies in the sheet "2.2 & 2.4.2 Cement & Binder".
B23: 1 | C23: Clinker | F23: BAU | G23: =+F24*G10 -> 9.91377 | H23: =+F24*H10 -> 13.022325
B24: 1.1 | D24: Volumen producción de Clinker | E24: Mt clinker | F24: =J24+M24+P24+S24 -> 8.4015 | G24: =K24+N24+Q24++T24 -> 9.2323807 | H24: =L24+O24+R24++U24 -> 10.454479 | J24: =J21*J22 -> 3.4515 | K24: =K21*K22 -> 4.0663891 | L24: =L21*L22 -> 5.1998955 | M24: =M21*M22 -> 3.77625 | N24: =N21*N22 -> 3.6950991 | O24: =O21*O22 -> 3.564333 | P24: =P21*P22 -> 0.67375 | Q24: =Q21*Q22 -> 0.72043712 | ... U24: =U21*U22 -> 0.84937201
B25: 1.2 | D25: Factor emisión CO2 del Clinker (= linea 1.2.4) | E25: kg CO2/kg clinker | F25: ='1.2 Clinker EF'!F44 -> 0.73709765 | G25: ='1.2 Clinker EF'!G44 -> 0.7373494 | H25: ='1.2 Clinker EF'!H44 -> 0.7024507 | W25: Value taken from sheet "1.2 Clinker EF" reflecting the CO2 mitigation and improvement of thermal energy efficiency in the clinker production process (excl. new binders, recarbonation and CCUS).
B26: 1.3 | D26: Emisiones de CO2 (excluyendo efecto de nuevos ligantes, recarbonatación y CCUS) | E26: Mt CO2 > | F26: =F24*F25 -> 6.1927259 | G26: =G24*G25 -> 6.8074903 | H26: =H24*H25 -> 7.3437559 | J26: Emissions from clay calcination | N26: 2020 | O26: 2030 | P26: 2050
B27: 1.4 | C27: New binders | H27: =+F26-H26 -> -1.15103 | J27: Share of calcined clay in binder volume | N27: 0 | O27: 0 | P27: 0
B28: 1.4.1 | D28: Porcentaje de ligantes nuevos utilizados en la producción de hormigón, referencia al volumen de ligante, línea 2.1 | E28: % share of binder volume in concrete | F28: 0 | G28: 0.01 | H28: 0.01 | J28: Volume of calcined clay [Mt] | N28: =F17*N27 -> 0 | O28: =G17*O27 -> 0 | P28: =H17*P27 -> 0 | S28: 0.225 | W28: Share of use of new binders in relation to the Binder volume in concrete (line 2.1).
B29: 1.4.2 | D29: Factor medio de emisión de CO2 de los nuevos ligantes | E29: kg CO2/kg new binder | G29: 0.4 | H29: 0.29 | J29: Emission factor of calcined clay [kg CO2/kg calc. clay] | N29: 0 | O29: 0 | P29: 0 | W29: Specific average CO2 emission factor of new binders. If different technologies apply, determine the input from a weighted average from the application of these technologies.Note that the CO2 efficiency of cements and binders based on cement is evolving in parallel according to the assumptions made in section 1 and 2.
B30: 1.4.3 | D30: Ahorro de emisiones de CO2 por el uso de nuevos aglutinantes (número positivo = ahorro en comparación con los cementos y aglutinantes a base de clínker) | E30: Mt CO2 | G30: =G17*G28*(G25*G19-G29) -> 0.01150919 | H30: =H17*H28*(H25*H19-H29) -> 0.024388906 | J30: Emissions from clay calcination [Mt CO2] | N30: =N28*N29 -> 0 | O30: =O28*O29 -> 0 | P30: =P28*P29 -> 0 | W30: The CO2 emission saving is accounted as additional saving from the application of new binder technologies relative to the efficient production of cements and binders based on clinker (as specified in section 1 and 2).
B31: 1.4.4 | D31: CO2 emissions (excluding recarbonation and CCUS) | E31: Mt CO2 > | F31: =N31-F30 -> 6.1927259 | G31: =O31-G30 -> 6.7959812 | H31: =P31-H30 -> 7.319367 | J31: CO2 emissions (incl. clay calcination) [Mt CO2] | N31: =F26+N30 -> 6.1927259 | O31: =G26+O30 -> 6.8074903 | P31: =H26+P30 -> 7.3437559
B32: 5 | C32: Recarbonation
B33: 5.1 | D33: Product life cycle partial recarbonation according to IVL study (conservative estimate in relation to process emissions) | E33: kg CO2/kg calcination CO2 | F33: 0.29 | J33: Indirect emissions from electricity | N33: 2020 | O33: 2030 | P33: 2050 | W33: Refer to sheet 'Info Recarbonation estimate' for an easy and refined estimate according to IVL study
B34: 5.2 | D34: Amount of recarbonated CO2 during product life cycle | E34: Mt CO2 | F34: =F24*'1.2 Clinker EF'!F11*$F$33 -> 1.2791284 | G34: =G24*'1.2 Clinker EF'!G11*$F$33 -> 1.40563 | H34: =H24*'1.2 Clinker EF'!H11*$F$33 -> 1.5916944 | J34: Factor emisión red eléctrica [g CO2/kWh] | N34: 272 | O34: 200 | P34: 14.1 | Q34: =+N34*0.001 -> 0.272 | R34: =+Q34*1000 -> 272
B35: 5.3 | D35: CO2 emissions (excluding effect of CCUS) | E35: Mt CO2 > | F35: =F31-F34 -> 4.9135975 | G35: =G31-G34 -> 5.3903512 | H35: =H31-H34 -> 5.7276726 | J35: Consumo eléctrico específico [kWh/t cement] | N35: ='1.2 Clinker EF'!F46 -> 120 | O35: ='1.2 Clinker EF'!G46 -> 115 | P35: ='1.2 Clinker EF'!H46 -> 87
B36: 6 | C36: Carbon Capture | G36: =+F35*0.25 -> 1.2283994 | H36: =+F35-G36 -> 3.6851981 | J36: Consumo eléctrico producción cemento [TWh] | N36: =N35*F21/1000 -> 1.506 | O36: =O35*G21/1000 -> 1.6262643 | P36: =P35*H21/1000 -> 1.4714596
B37: 6.1 | D37: Cantidad de CO2 capturado para uso y/o almacenamiento (CCUS) | E37: Mt CO2 | F37: 0 | G37: 0 | H37: =+H35 -> 5.7276726 | J37: Consumo eléctrico adicional de CCUS [kWh/t clinker] | N37: 0 | O37: 0 | P37: 200 | Q37: Ocupando u tercio de la prod de ckmestara cubierta con CCUS. Paper 50, con eificiencia 80% | W37: Enter the absolute amount of CO2 captured and used or permanently stored in Mt CO2. E.g. if for 2050 the value for line 6.1 is equal to line 5.3, the calculation results in no residual CO2 emissions or carbon neutrality in line 6.3.
B38: 6.2 | D38: Cantidad equivalente producción clínker con captura de carbono al 90% eficiencia de captura CO2 de la cadena completa de CCUS | E38: Mt clinker produced with CCUS | F38: =F24*(F37/0.9)/F31 -> 0 | G38: =G24*(G37/0.9)/G31 -> 0 | H38: =H24*(H37/0.9)/H31 -> 9.0900137 | J38: Consumo eléctrico de CCUS [TWh] | N38: =N37*F24/1000 -> 0 | O38: =O37*G38/1000 -> 0 | P38: =P37*H24/1000 -> 2.0908957 | W38: This line is for information. It provieds a rough estimate of the clinker production volume that is assumed to be equipped with CCUS technology. The value should not exceed the value clinker productin volume determined in line 1.1. In this estimate a capture efficency of 90% is assumed, accounding for some efficiency losses in the capture process itself and in the CCUS chain, e.g. direct or indirect CO2 emissions during CO2 processing, transport and intermediate storage.
B39: 6.3 | D39: Emisiones de CO2 residuales (incluido el efecto de CCUS) | E39: Mt CO2 > | F39: =F35-F37 -> 4.9135975 | G39: =G35-G37 -> 5.3903512 | H39: =H35-H37 -> 0 | J39: Consumo eléctrico adicional en concreto [kWh/m3] | N39: 3 | O39: 3 | P39: 5
J40: Consumo eléctrico de mezcla concreto [TWh] | N40: =N54*N39 -> 0.039715936 | O40: =O54*O39 -> 0.051092906 | P40: =P54*P39 -> 0.13143241
...

Sheet Waterfall data
E1: Reference | P1: Waterafall data for construction of diagrams
E2: Region | F2: ='Whole life model'!F2 -> ARGENTINA
E3: Organisation | F3: ='Whole life model'!F3 -> AFCP
E4: corresponding author | F4: ='Whole life model'!F4 -> FICEM and AFCP
E5: E-mail contact | F5: ='Whole life model'!F5 -> maria.lefevre@afcp.org.ar
E6: Phone contact | F6: ='Whole life model'!F6 -> Phone
E7: Reference year | F7: ='Whole life model'!F7 -> 2020 | G7: ='Whole life model'!G7 -> 2030 | H7: ='Whole life model'!H7 -> 2050 | I7: ='Whole life model'!F7 -> 2020 | J7: ='Whole life model'!G7 -> 2030 | K7: ='Whole life model'!H7 -> 2050 | L7: ='Whole life model'!F7 -> 2020 | M7: ='Whole life model'!G7 -> 2030 | N7: ='Whole life model'!H7 -> 2050
G8: Waterfall diagram data | J8: Direct emissions | M8: Indirect emissions | P8: Waterfall diagram data for GCCA CO2 roadmap status quo to 2030 | Y8: Waterfall diagram data for GCCA CO2 roadmap status quo to 2050
B9: 8 | C9: Absolute CO2 | D9: direct emissions from clinker production, calcination and fuel CO2, basis for waterfall diagram | Q9: Direct CO2 emissions (Mt CO2) | R9: Indirect CO2 emissions (Mt CO2) | S9: increase (blue) | T9: decrease (green) | U9: (white) | Z9: Direct CO2 emissions (Mt CO2) | AA9: Indirect CO2 emissions (Mt CO2) | AB9: increase (blue) | AC9: decrease (green) | AD9: (white)
B10: 8.00 | D10: CO2 reference (status quo) | E10: Mt CO2 | F10: =I10+L10 -> 6.6131606 | G10: =J10+M10 -> 6.6131606 | H10: =K10+N10 -> 6.6131606 | I10: ='Whole life model'!$F$26 -> 6.1927259 | J10: ='Whole life model'!$F$26 -> 6.1927259 | K10: ='Whole life model'!$F$26 -> 6.1927259 | L10: ='Whole life model'!$N$42 -> 0.42043473 | M10: ='Whole life model'!$N$42 -> 0.42043473 | N10: ='Whole life model'!$N$42 -> 0.42043473 | P10: ='Whole life model'!F7 -> 2020 | Q10: =J10 -> 6.1927259 | R10: =M10 -> 0.42043473 | V10: =G10 -> 6.6131606 | Y10: ='Whole life model'!F7 -> 2020 | Z10: =K10 -> 6.1927259 | AA10: =N10 -> 0.42043473 | AE10: =H10 -> 6.6131606
B11: 8.0 | D11: CO2 according to societal demand changes (status quo technology) | E11: Mt CO2 | F11: =I11+L11 -> 6.6131606 | G11: =J11+M11 -> 7.8035296 | H11: =K11+N11 -> 10.250399 | I11: =I$10*'Whole life model'!F10 -> 6.1927259 | J11: =J$10*'Whole life model'!G10 -> 7.3074166 | K11: =K$10*'Whole life model'!H10 -> 9.5987252 | L11: =L$10*'Whole life model'!F10 -> 0.42043473 | M11: =M$10*'Whole life model'!G10 -> 0.49611299 | N11: =N$10*'Whole life model'!H10 -> 0.65167384 | P11: Societal demand | S11: =IF(V11>W11,V11-U11,"") -> 1.1903689 | T11: =IF(V11<W11,W11-U11,"") | U11: =MIN(V11:W11) -> 6.6131606 | V11: =G11 -> 7.8035296 | W11: =V11-G23 -> 6.6131606 | Y11: Societal demand | AB11: =IF(AE11>AF11,AE11-AD11,"") -> 3.6372384 | AC11: =IF(AE11<AF11,AF11-AD11,"") | AD11: =MIN(AE11:AF11) -> 6.6131606 | AE11: =H11 -> 10.250399 | AF11: =AE11-H23 -> 6.6131606
B12: 8.4 | D12: CO2 emission with additional measures in section design & construction | E12: Mt CO2 | F12: =I12+L12 -> 6.6131606 | G12: =J12+M12 -> 7.4590285 | H12: =K12+N12 -> 9.4079594 | I12: =I11*('Whole life model'!F13/'Whole life model'!$F13) -> 6.1927259 | J12: =J11*('Whole life model'!G13/'Whole life model'!$F13) -> 6.9848174 | K12: =K11*('Whole life model'!H13/'Whole life model'!$F13) -> 8.809844 | L12: =L11*('Whole life model'!F13/'Whole life model'!$F13) -> 0.42043473 | M12: =M11*('Whole life model'!G13/'Whole life model'!$F13) -> 0.47421118 | N12: =N11*('Whole life model'!H13/'Whole life model'!$F13) -> 0.59811535 | P12: Design & Construction | S12: =IF(V12>W12,V12-U12,"") | T12: =IF(V12<W12,W12-U12,"") -> 0.34450103 | U12: =MIN(V12:W12) -> 7.4590285 | V12: =G12 -> 7.4590285 | W12: =V12-G24 -> 7.8035296 | Y12: Design&Construction | AB12: =IF(AE12>AF12,AE12-AD12,"") | AC12: =IF(AE12<AF12,AF12-AD12,"") -> 0.84243964 | AD12: =MIN(AE12:AF12) -> 9.4079594 | AE12: =H12 -> 9.4079594 | AF12: =AE12-H24 -> 10.250399 | AG12: =+AC12/AE$11 -> 0.082186034
B13: 8.3 | D13: CO2 emission with additional measures in section concrete | E13: Mt CO2 | F13: =I13+L13 -> 6.6131606 | G13: =J13+M13 -> 7.451756 | H13: =K13+N13 -> 8.9123951 | I13: =I12*('Whole life model'!F15/'Whole life model'!$F15) -> 6.1927259 | J13: =J12*('Whole life model'!G15/'Whole life model'!$F15) -> 6.9780072 | K13: =K12*('Whole life model'!H15/'Whole life model'!$F15) -> 8.3457855 | L13: =L12*('Whole life model'!F15/'Whole life model'!$F15) -> 0.42043473 | M13: =M12*('Whole life model'!G15/'Whole life model'!$F15) -> 0.47374882 | N13: =N12*('Whole life model'!H15/'Whole life model'!$F15) -> 0.56660962 | P13: Concrete | S13: =IF(V13>W13,V13-U13,"") | T13: =IF(V13<W13,W13-U13,"") -> 0.0072725528 | U13: =MIN(V13:W13) -> 7.451756 | V13: =G13 -> 7.451756 | W13: =V13-G25 -> 7.4590285 | Y13: Concrete | AB13: =IF(AE13>AF13,AE13-AD13,"") | AC13: =IF(AE13<AF13,AF13-AD13,"") -> 0.49556426 | AD13: =MIN(AE13:AF13) -> 8.9123951 | AE13: =H13 -> 8.9123951 | AF13: =AE13-H25 -> 9.4079594 | AG13: =+AC13/AE$11 -> 0.048345851
B14: 8.2 | D14: CO2 emission with additional measures in section cement & binders (incl. SCM) | E14: Mt CO2 | F14: =I14+L14 -> 6.6131606 | G14: =J14+M14 -> 7.2789149 | H14: =K14+N14 -> 8.2725813 | I14: =I13*('Whole life model'!F19/'Whole life model'!$F19)*('Whole life model'!N31/'Whole life model'!F26) -> 6.1927259 | J14: =J13*('Whole life model'!G19/'Whole life model'!$F19)*('Whole life model'!O31/'Whole life model'!G26) -> 6.8051661 | K14: =K13*('Whole life model'!H19/'Whole life model'!$F19)*('Whole life model'!P31/'Whole life model'!H26) -> 7.7059717 | L14: =L13 -> 0.42043473 | M14: =M13 -> 0.47374882 | N14: =N13 -> 0.56660962 | P14: Cement & binders | S14: =IF(V14>W14,V14-U14,"") | T14: =IF(V14<W14,W14-U14,"") -> 0.17284107 | U14: =MIN(V14:W14) -> 7.2789149 | V14: =G14 -> 7.2789149 | W14: =V14-G26 -> 7.451756 | Y14: Cement & binders | AB14: =IF(AE14>AF14,AE14-AD14,"") | AC14: =IF(AE14<AF14,AF14-AD14,"") -> 0.63981376 | AD14: =MIN(AE14:AF14) -> 8.2725813 | AE14: =H14 -> 8.2725813 | AF14: =AE14-H26 -> 8.9123951 | AG14: =+AC14/AE$11 -> 0.062418425
B15: 8.1.4 | D15: CO2 emission with additional measures in section new binders | E15: Mt CO3 | F15: =I15+L15 -> 6.6131606 | G15: =J15+M15 -> 7.2674097 | H15: =K15+N15 -> 8.2469895 | I15: =I14*('Whole life model'!F31/'Whole life model'!N31) -> 6.1927259 | J15: =J14*('Whole life model'!G31/'Whole life model'!O31) -> 6.7936608 | K15: =K14*('Whole life model'!H31/'Whole life model'!P31) -> 7.6803799 | L15: =L14 -> 0.42043473 | M15: =M14 -> 0.47374882 | N15: =N14 -> 0.56660962 | P15: New binders | S15: =IF(V15>W15,V15-U15,"") | T15: =IF(V15<W15,W15-U15,"") -> 0.01150526 | U15: =MIN(V15:W15) -> 7.2674097 | V15: =G15 -> 7.2674097 | W15: =V15-G27 -> 7.2789149 | Y15: New binders | AB15: =IF(AE15>AF15,AE15-AD15,"") | AC15: =IF(AE15<AF15,AF15-AD15,"") -> 0.02559184 | AD15: =MIN(AE15:AF15) -> 8.2469895 | AE15: =H15 -> 8.2469895 | AF15: =AE15-H27 -> 8.2725813 | AG15: =+AC15/AE$11 -> 0.0024966676
D16: CO2 emission with additional decarbonisation of electricity mix | E16: Mt CO2 | F16: =I16+L16 -> 6.6131606 | G16: =J16+M16 -> 7.1291323 | H16: =K16+N16 -> 7.7324623 | I16: =I15 -> 6.1927259 | J16: =J15 -> 6.7936608 | K16: =K15 -> 7.6803799 | L16: ='Whole life model'!N42 -> 0.42043473 | M16: ='Whole life model'!O42 -> 0.33547143 | N16: ='Whole life model'!P42 -> 0.052082407 | P16: Electricity | S16: =IF(V16>W16,V16-U16,"") | T16: =IF(V16<W16,W16-U16,"") -> 0.13827739 | U16: =MIN(V16:W16) -> 7.1291323 | V16: =G16 -> 7.1291323 | W16: =V16-G28 -> 7.2674097 | Y16: Electricity | AB16: =IF(AE16>AF16,AE16-AD16,"") | AC16: =IF(AE16<AF16,AF16-AD16,"") -> 0.51452722 | AD16: =MIN(AE16:AF16) -> 7.7324623 | AE16: =H16 -> 7.7324623 | AF16: =AE16-H28 -> 8.2469895 | AG16: =+AC16/AE$11 -> 0.050195823
B17: 8.1 | D17: CO2 emission with additional measures in section clinker | E17: Mt CO2 | F17: =I17+L17 -> 6.6131606 | G17: =J17+M17 -> 7.1314526 | H17: =K17+N17 -> 7.3714494 | I17: =I16*('Whole life model'!F25/'Whole life model'!$F25) -> 6.1927259 | J17: =J16*('Whole life model'!G25/'Whole life model'!$F25) -> 6.7959812 | K17: =K16*('Whole life model'!H25/'Whole life model'!$F25) -> 7.319367 | L17: =L16 -> 0.42043473 | M17: =M16 -> 0.33547143 | N17: =N16 -> 0.052082407 | P17: Clinker | S17: =IF(V17>W17,V17-U17,"") -> 0.0023203223 | T17: =IF(V17<W17,W17-U17,"") | U17: =MIN(V17:W17) -> 7.1291323 | V17: =G17 -> 7.1314526 | W17: =V17-G29 -> 7.1291323 | Y17: Clinker | AB17: =IF(AE17>AF17,AE17-AD17,"") | AC17: =IF(AE17<AF17,AF17-AD17,"") -> 0.36101287 | AD17: =MIN(AE17:AF17) -> 7.3714494 | AE17: =H17 -> 7.3714494 | AF17: =AE17-H29 -> 7.7324623 | AG17: =+AC17/AE$11 -> 0.035219397
B18: 8.5 | D18: CO2 emission with accounting of partial recarbonation (= line 5.3) | E18: Mt CO2 | F18: =I18+L18 -> 5.3340323 | G18: =J18+M18 -> 5.7258226 | H18: =K18+N18 -> 5.779755 | I18: =I17-'Whole life model'!F34 -> 4.9135975 | J18: =J17-'Whole life model'!G34 -> 5.3903512 | K18: =K17-'Whole life model'!H34 -> 5.7276726 | L18: =L17 -> 0.42043473 | M18: =M17 -> 0.33547143 | N18: =N17 -> 0.052082407 | P18: Recarbonation | S18: =IF(V18>W18,V18-U18,"") | T18: =IF(V18<W18,W18-U18,"") -> 1.40563 | U18: =MIN(V18:W18) -> 5.7258226 | V18: =G18 -> 5.7258226 | W18: =V18-G30 -> 7.1314526 | Y18: Recarbonation | AB18: =IF(AE18>AF18,AE18-AD18,"") | AC18: =IF(AE18<AF18,AF18-AD18,"") -> 1.5916944 | AD18: =MIN(AE18:AF18) -> 5.779755 | AE18: =H18 -> 5.779755 | AF18: =AE18-H30 -> 7.3714494 | AG18: =+AC18/AE$11 -> 0.15528121
